<?xml version="1.0" ?>
<!-- =================================================================================== -->
<!-- |    This document was autogenerated by xacro from /home/shinas/ros2/freddy/src/freddy_description/freddy_description/robots/freddy.urdf.xacro | -->
<!-- |    EDITING THIS FILE BY HAND IS NOT RECOMMENDED                                 | -->
<!-- =================================================================================== -->
<robot name="freddy">
  <material name="Orange">
    <color rgba="1.0 0.4 0.0 1.0"/>
  </material>
  <material name="Grey">
    <color rgba="0.7 0.7 0.7 1.0"/>
  </material>
  <material name="DarkGrey">
    <color rgba="0.3 0.3 0.3 1.0"/>
  </material>
  <material name="White">
    <color rgba="1.0 1.0 1.0 1.0"/>
  </material>
  <material name="Black">
    <color rgba="0.0 0.0 0.0 1.0"/>
  </material>
  <material name="Red">
    <color rgba="1.0 0.0 0.0 1.0"/>
  </material>
  <material name="Green">
    <color rgba="0.0 1.0 0.0 1.0"/>
  </material>
  <material name="Blue">
    <color rgba="0.0 0.0 0.8 1.0"/>
  </material>
  <material name="LightGrey">
    <color rgba="0.82 0.82 0.82 1.0"/>
  </material>
  <link name="base_link"/>
  <!-- HOLONOMIC DRIVE PLUGIN -->
  <gazebo>
    <plugin filename="libgazebo_ros_planar_move.so" name="gazebo_ros_planar_move">
      <commandTopic>cmd_vel</commandTopic>
      <odometryTopic>odom</odometryTopic>
      <odometryFrame>odom</odometryFrame>
      <odometryRate>20.0</odometryRate>
      <robotBaseFrame>base_link</robotBaseFrame>
    </plugin>
  </gazebo>
  <!-- BASE -->
  <joint name="freddy_base_joint" type="fixed">
    <origin rpy="0.0 0.0 0.0" xyz="0.0 0.0 0.0"/>
    <parent link="base_link"/>
    <child link="freddy_base_link"/>
  </joint>
  <link name="freddy_base_link">
    <visual>
      <origin rpy="0 0 0" xyz="0 0 0.16"/>
      <geometry>
        <box size="0.635 0.582 0.12"/>
      </geometry>
      <material name="DarkGrey"/>
    </visual>
    <visual>
      <origin rpy="0 0 0" xyz="0 0 0.245"/>
      <geometry>
        <box size="0.44449999999999995 0.40739999999999993 0.05"/>
      </geometry>
      <material name="DarkGrey"/>
    </visual>
    <visual>
      <origin rpy="0 0 0" xyz="0 0 0.32"/>
      <geometry>
        <box size="0.635 0.582 0.1"/>
      </geometry>
      <material name="DarkGrey"/>
    </visual>
    <!-- base bottom collisions -->
    <collision>
      <origin rpy="0 0 0.0" xyz="0 0 0.16"/>
      <geometry>
        <box size="0.635 0.582 0.12"/>
      </geometry>
    </collision>
    <!-- base top collisions -->
    <collision>
      <origin rpy="0 0 0.0" xyz="0 0 0.32"/>
      <geometry>
        <box size="0.635 0.582 0.1"/>
      </geometry>
    </collision>
    <inertial>
      <origin rpy="0 0 0" xyz="0 0 0"/>
      <mass value="40.0"/>
      <inertia ixx="1.37208" ixy="0.0" ixz="0.0" iyy="1.5870833333333334" iyz="0.0" izz="2.4731633333333334"/>
    </inertial>
  </link>
  <gazebo reference="freddy_base_link">
    <material>Gazebo/RustySteel</material>
  </gazebo>
  <joint name="left_front_wheel_joint" type="fixed">
    <origin rpy="0 0 0" xyz="0.2675                          0.241                          0.05"/>
    <parent link="freddy_base_link"/>
    <child link="left_front_wheel_link"/>
  </joint>
  <link name="left_front_wheel_link">
    <visual>
      <geometry>
        <sphere radius="0.05"/>
      </geometry>
      <material name="Black"/>
    </visual>
    <collision>
      <geometry>
        <sphere radius="0.05"/>
      </geometry>
    </collision>
    <inertial>
      <origin rpy="0 0 0" xyz="0 0 0"/>
      <mass value="1.0"/>
      <inertia ixx="0.0010000000000000002" ixy="0.0" ixz="0.0" iyy="0.0010000000000000002" iyz="0.0" izz="0.0010000000000000002"/>
    </inertial>
  </link>
  <gazebo reference="left_front_wheel_link">
    <mu1>0.0</mu1>
    <mu2>0.0</mu2>
    <material>Gazebo/Black</material>
  </gazebo>
  <joint name="right_front_wheel_joint" type="fixed">
    <origin rpy="0 0 0" xyz="0.2675                          -0.241                          0.05"/>
    <parent link="freddy_base_link"/>
    <child link="right_front_wheel_link"/>
  </joint>
  <link name="right_front_wheel_link">
    <visual>
      <geometry>
        <sphere radius="0.05"/>
      </geometry>
      <material name="Black"/>
    </visual>
    <collision>
      <geometry>
        <sphere radius="0.05"/>
      </geometry>
    </collision>
    <inertial>
      <origin rpy="0 0 0" xyz="0 0 0"/>
      <mass value="1.0"/>
      <inertia ixx="0.0010000000000000002" ixy="0.0" ixz="0.0" iyy="0.0010000000000000002" iyz="0.0" izz="0.0010000000000000002"/>
    </inertial>
  </link>
  <gazebo reference="right_front_wheel_link">
    <mu1>0.0</mu1>
    <mu2>0.0</mu2>
    <material>Gazebo/Black</material>
  </gazebo>
  <joint name="left_back_wheel_joint" type="fixed">
    <origin rpy="0 0 0" xyz="-0.2675                          0.241                          0.05"/>
    <parent link="freddy_base_link"/>
    <child link="left_back_wheel_link"/>
  </joint>
  <link name="left_back_wheel_link">
    <visual>
      <geometry>
        <sphere radius="0.05"/>
      </geometry>
      <material name="Black"/>
    </visual>
    <collision>
      <geometry>
        <sphere radius="0.05"/>
      </geometry>
    </collision>
    <inertial>
      <origin rpy="0 0 0" xyz="0 0 0"/>
      <mass value="1.0"/>
      <inertia ixx="0.0010000000000000002" ixy="0.0" ixz="0.0" iyy="0.0010000000000000002" iyz="0.0" izz="0.0010000000000000002"/>
    </inertial>
  </link>
  <gazebo reference="left_back_wheel_link">
    <mu1>0.0</mu1>
    <mu2>0.0</mu2>
    <material>Gazebo/Black</material>
  </gazebo>
  <joint name="right_back_wheel_joint" type="fixed">
    <origin rpy="0 0 0" xyz="-0.2675                          -0.241                          0.05"/>
    <parent link="freddy_base_link"/>
    <child link="right_back_wheel_link"/>
  </joint>
  <link name="right_back_wheel_link">
    <visual>
      <geometry>
        <sphere radius="0.05"/>
      </geometry>
      <material name="Black"/>
    </visual>
    <collision>
      <geometry>
        <sphere radius="0.05"/>
      </geometry>
    </collision>
    <inertial>
      <origin rpy="0 0 0" xyz="0 0 0"/>
      <mass value="1.0"/>
      <inertia ixx="0.0010000000000000002" ixy="0.0" ixz="0.0" iyy="0.0010000000000000002" iyz="0.0" izz="0.0010000000000000002"/>
    </inertial>
  </link>
  <gazebo reference="right_back_wheel_link">
    <mu1>0.0</mu1>
    <mu2>0.0</mu2>
    <material>Gazebo/Black</material>
  </gazebo>
  <joint name="base_laser_front_joint" type="fixed">
    <axis xyz="0 1 0"/>
    <origin rpy="3.141592653589793 0 -0.7853981633974483" xyz="0.26 -0.24 0.25"/>
    <parent link="freddy_base_link"/>
    <child link="base_laser_front_link"/>
  </joint>
  <link name="base_laser_front_link">
    <inertial>
      <mass value="0.16"/>
      <origin rpy="0 0 0" xyz="0 0 0"/>
      <inertia ixx="0.1" ixy="0" ixz="0" iyy="0.1" iyz="0" izz="0.1"/>
    </inertial>
    <visual>
      <origin rpy="0 0 0" xyz="0 0 0"/>
      <geometry>
        <mesh filename="package://freddy_base_description/meshes/sensors/hokuyo.dae"/>
      </geometry>
    </visual>
    <collision>
      <origin rpy="0 0 0" xyz="0 0 0"/>
      <geometry>
        <mesh filename="package://freddy_base_description/meshes/sensors/hokuyo_convex.dae"/>
      </geometry>
    </collision>
  </link>
  <gazebo reference="base_laser_front_link">
    <!-- <turnGravityOff>true</turnGravityOff> -->
    <sensor name="base_laser_front" type="ray">
      <pose>0 0 0 0 0 0</pose>
      <visualize>False</visualize>
      <update_rate>40</update_rate>
      <ray>
        <scan>
          <horizontal>
            <samples>1080</samples>
            <resolution>1</resolution>
            <min_angle>-2.35619</min_angle>
            <max_angle>2.35619</max_angle>
          </horizontal>
        </scan>
        <range>
          <min>0.06</min>
          <max>10.0</max>
          <resolution>0.01</resolution>
        </range>
        <noise>
          <type>gaussian</type>
          <mean>0.0</mean>
          <stddev>0.005</stddev>
        </noise>
      </ray>
      <plugin filename="libgazebo_ros_laser.so" name="base_laser_front_controller">
        <topicName>/freddy/base_scan_front</topicName>
        <frameName>base_laser_front_link</frameName>
        <robotNamespace>/</robotNamespace>
      </plugin>
    </sensor>
  </gazebo>
  <joint name="base_laser_back_joint" type="fixed">
    <axis xyz="0 1 0"/>
    <origin rpy="3.141592653589793 0 2.356194490192345" xyz="-0.26 0.24 0.25"/>
    <parent link="freddy_base_link"/>
    <child link="base_laser_back_link"/>
  </joint>
  <link name="base_laser_back_link">
    <inertial>
      <mass value="0.16"/>
      <origin rpy="0 0 0" xyz="0 0 0"/>
      <inertia ixx="0.1" ixy="0" ixz="0" iyy="0.1" iyz="0" izz="0.1"/>
    </inertial>
    <visual>
      <origin rpy="0 0 0" xyz="0 0 0"/>
      <geometry>
        <mesh filename="package://freddy_base_description/meshes/sensors/hokuyo.dae"/>
      </geometry>
    </visual>
    <collision>
      <origin rpy="0 0 0" xyz="0 0 0"/>
      <geometry>
        <mesh filename="package://freddy_base_description/meshes/sensors/hokuyo_convex.dae"/>
      </geometry>
    </collision>
  </link>
  <gazebo reference="base_laser_back_link">
    <!-- <turnGravityOff>true</turnGravityOff> -->
    <sensor name="base_laser_back" type="ray">
      <pose>0 0 0 0 0 0</pose>
      <visualize>False</visualize>
      <update_rate>40</update_rate>
      <ray>
        <scan>
          <horizontal>
            <samples>1080</samples>
            <resolution>1</resolution>
            <min_angle>-2.35619</min_angle>
            <max_angle>2.35619</max_angle>
          </horizontal>
        </scan>
        <range>
          <min>0.06</min>
          <max>10.0</max>
          <resolution>0.01</resolution>
        </range>
        <noise>
          <type>gaussian</type>
          <mean>0.0</mean>
          <stddev>0.005</stddev>
        </noise>
      </ray>
      <plugin filename="libgazebo_ros_laser.so" name="base_laser_back_controller">
        <topicName>/freddy/base_scan_back</topicName>
        <frameName>base_laser_back_link</frameName>
        <robotNamespace>/</robotNamespace>
      </plugin>
    </sensor>
  </gazebo>
  <!-- TORSO -->
  <joint name="freddy_torso_joint" type="fixed">
    <origin rpy="0 0 0" xyz="-0.20249999999999999 0 0.37"/>
    <parent link="base_link"/>
    <child link="freddy_torso_link"/>
  </joint>
  <link name="freddy_torso_link">
    <visual>
      <origin rpy="0 0 0" xyz="0 0 0.15"/>
      <geometry>
        <box size="0.19 0.4 0.3"/>
      </geometry>
      <material name="Grey"/>
    </visual>
    <!-- torso collision -->
    <collision>
      <origin rpy="0 0 0" xyz="0 0 0.15"/>
      <geometry>
        <box size="0.19 0.4 0.3"/>
      </geometry>
    </collision>
    <inertial>
      <origin rpy="0 0 0" xyz="0 0 0"/>
      <mass value="40.0"/>
      <inertia ixx="1.37208" ixy="0.0" ixz="0.0" iyy="1.5870833333333334" iyz="0.0" izz="2.4731633333333334"/>
    </inertial>
  </link>
  <!-- TORSO SHOULDER LEFT -->
  <joint name="freddy_torso_shoulder_left_joint" type="fixed">
    <origin rpy="0. 0.1309 0.7853982" xyz="0.085 0 0.27"/>
    <parent link="freddy_torso_link"/>
    <child link="freddy_torso_shoulder_left_link"/>
  </joint>
  <link name="freddy_torso_shoulder_left_link">
    <visual>
      <origin rpy="0 0 0" xyz="0 0.1 0.1"/>
      <geometry>
        <box size="0.02 0.2 0.2"/>
      </geometry>
      <material name="Grey"/>
    </visual>
    <!-- torso shoulder collision -->
    <collision>
      <origin rpy="0 0 0" xyz="0 0 -0.01"/>
      <geometry>
        <box size="0.02 0.2 0.2"/>
      </geometry>
    </collision>
    <inertial>
      <origin rpy="0 0 0" xyz="0 0 0"/>
      <mass value="40.0"/>
      <inertia ixx="1.37208" ixy="0.0" ixz="0.0" iyy="1.5870833333333334" iyz="0.0" izz="2.4731633333333334"/>
    </inertial>
  </link>
  <joint name="freddy_torso_shoulder_left_arm_joint" type="fixed">
    <origin rpy="3.14159 -1.5708 0" xyz="0 0.1 0.1"/>
    <parent link="freddy_torso_shoulder_left_link"/>
    <child link="freddy_torso_shoulder_left_arm_attach_link"/>
  </joint>
  <link name="freddy_torso_shoulder_left_arm_attach_link"/>
  <!-- TORSO SHOULDER RIGHT -->
  <joint name="freddy_torso_shoulder_right_joint" type="fixed">
    <origin rpy="0 0.1309 -0.7853982" xyz="0.085 0 0.27"/>
    <parent link="freddy_torso_link"/>
    <child link="freddy_torso_shoulder_right_link"/>
  </joint>
  <link name="freddy_torso_shoulder_right_link">
    <visual>
      <origin rpy="0 0 0" xyz="0 -0.1 0.1"/>
      <geometry>
        <box size="0.02 0.2 0.2"/>
      </geometry>
      <material name="Grey"/>
    </visual>
    <!-- torso shoulder collision -->
    <collision>
      <origin rpy="0 0 0" xyz="0 0 -0.01"/>
      <geometry>
        <box size="0.02 0.2 0.2"/>
      </geometry>
    </collision>
    <inertial>
      <origin rpy="0 0 0" xyz="0 0 0"/>
      <mass value="40.0"/>
      <inertia ixx="1.37208" ixy="0.0" ixz="0.0" iyy="1.5870833333333334" iyz="0.0" izz="2.4731633333333334"/>
    </inertial>
  </link>
  <joint name="freddy_torso_shoulder_right_arm_joint" type="fixed">
    <origin rpy="3.14159 -1.5708 0" xyz="0 -0.1 0.1"/>
    <parent link="freddy_torso_shoulder_right_link"/>
    <child link="freddy_torso_shoulder_right_arm_attach_link"/>
  </joint>
  <link name="freddy_torso_shoulder_right_arm_attach_link"/>
  <gazebo reference="freddy_torso_link">
    <material>Gazebo/RustySteel</material>
  </gazebo>
  <!-- arms -->
  <ros2_control name="kinova_left_KortexMultiInterfaceHardware" type="system">
    <hardware>
      <plugin>kortex_driver/KortexMultiInterfaceHardware</plugin>
      <param name="robot_ip">192.168.1.10</param>
      <param name="username">admin</param>
      <param name="password">admin</param>
      <param name="port">10000</param>
      <param name="port_realtime">10001</param>
      <param name="session_inactivity_timeout_ms">60000</param>
      <param name="connection_inactivity_timeout_ms">2000</param>
      <param name="tf_prefix">&quot;&quot;</param>
      <param name="use_internal_bus_gripper_comm">False</param>
      <param name="gripper_joint_name">finger_joint</param>
      <param name="gripper_max_velocity">100.0</param>
      <param name="gripper_max_force">100.0</param>
    </hardware>
    <joint name="kinova_left_joint_1">
      <command_interface name="position">
        <param name="min">{-2*pi}</param>
        <param name="max">{2*pi}</param>
      </command_interface>
      <state_interface name="position">
        <param name="initial_value">-0.517734469311598</param>
      </state_interface>
      <state_interface name="velocity"/>
      <state_interface name="effort"/>
    </joint>
    <joint name="kinova_left_joint_2">
      <command_interface name="position">
        <param name="min">-2.41</param>
        <param name="max">2.41</param>
      </command_interface>
      <state_interface name="position">
        <param name="initial_value">-0.08483200000000002</param>
      </state_interface>
      <state_interface name="velocity"/>
      <state_interface name="effort"/>
    </joint>
    <joint name="kinova_left_joint_3">
      <command_interface name="position">
        <param name="min">{-2*pi}</param>
        <param name="max">{2*pi}</param>
      </command_interface>
      <state_interface name="position">
        <param name="initial_value">1.7743715307475147</param>
      </state_interface>
      <state_interface name="velocity"/>
      <state_interface name="effort"/>
    </joint>
    <joint name="kinova_left_joint_4">
      <command_interface name="position">
        <param name="min">-2.66</param>
        <param name="max">2.66</param>
      </command_interface>
      <state_interface name="position">
        <param name="initial_value">-1.4395920000000002</param>
      </state_interface>
      <state_interface name="velocity"/>
      <state_interface name="effort"/>
    </joint>
    <joint name="kinova_left_joint_5">
      <command_interface name="position">
        <param name="min">{-2*pi}</param>
        <param name="max">{2*pi}</param>
      </command_interface>
      <state_interface name="position">
        <param name="initial_value">0.0</param>
      </state_interface>
      <state_interface name="velocity"/>
      <state_interface name="effort"/>
    </joint>
    <joint name="kinova_left_joint_6">
      <command_interface name="position">
        <param name="min">-2.23</param>
        <param name="max">2.23</param>
      </command_interface>
      <state_interface name="position">
        <param name="initial_value">-0.708248</param>
      </state_interface>
      <state_interface name="velocity"/>
      <state_interface name="effort"/>
    </joint>
    <joint name="kinova_left_joint_7">
      <command_interface name="position">
        <param name="min">{-2*pi}</param>
        <param name="max">{2*pi}</param>
      </command_interface>
      <state_interface name="position">
        <param name="initial_value">0.0</param>
      </state_interface>
      <state_interface name="velocity"/>
      <state_interface name="effort"/>
    </joint>
  </ros2_control>
  <joint name="kinova_left_base_joint" type="fixed">
    <origin rpy="0 0 0" xyz="0 0 0"/>
    <parent link="freddy_torso_shoulder_left_arm_attach_link"/>
    <child link="kinova_left_base_link"/>
  </joint>
  <link name="kinova_left_base_link">
    <inertial>
      <origin rpy="0 0 0" xyz="-0.000648 -0.000166 0.084487"/>
      <mass value="1.697"/>
      <inertia ixx="0.004622" ixy="9E-06" ixz="6E-05" iyy="0.004495" iyz="9E-06" izz="0.002079"/>
    </inertial>
    <visual>
      <origin rpy="0 0 0" xyz="0 0 0"/>
      <geometry>
        <mesh filename="file:///home/shinas/ros2/freddy/install/kortex_description/share/kortex_description/arms/gen3/7dof/meshes/base_link.dae"/>
      </geometry>
      <material name="">
        <color rgba="0.75294 0.75294 0.75294 1"/>
      </material>
    </visual>
    <collision>
      <origin rpy="0 0 0" xyz="0 0 0"/>
      <geometry>
        <mesh filename="file:///home/shinas/ros2/freddy/install/kortex_description/share/kortex_description/arms/gen3/7dof/meshes/base_link.dae"/>
      </geometry>
    </collision>
  </link>
  <link name="kinova_left_shoulder_link">
    <inertial>
      <origin rpy="0 0 0" xyz="-2.3E-05 -0.010364 -0.07336"/>
      <mass value="1.3773"/>
      <inertia ixx="0.00457" ixy="1E-06" ixz="2E-06" iyy="0.004831" iyz="0.000448" izz="0.001409"/>
    </inertial>
    <visual>
      <origin rpy="0 0 0" xyz="0 0 0"/>
      <geometry>
        <mesh filename="file:///home/shinas/ros2/freddy/install/kortex_description/share/kortex_description/arms/gen3/7dof/meshes/shoulder_link.dae"/>
      </geometry>
      <material name="">
        <color rgba="0.75294 0.75294 0.75294 1"/>
      </material>
    </visual>
    <collision>
      <origin rpy="0 0 0" xyz="0 0 0"/>
      <geometry>
        <mesh filename="file:///home/shinas/ros2/freddy/install/kortex_description/share/kortex_description/arms/gen3/7dof/meshes/shoulder_link.dae"/>
      </geometry>
    </collision>
  </link>
  <joint name="kinova_left_joint_1" type="continuous">
    <origin rpy="3.1416 2.7629E-18 -4.9305E-36" xyz="0 0 0.15643"/>
    <parent link="kinova_left_base_link"/>
    <child link="kinova_left_shoulder_link"/>
    <axis xyz="0 0 1"/>
    <limit effort="39" velocity="1.3963"/>
  </joint>
  <link name="kinova_left_half_arm_1_link">
    <inertial>
      <origin rpy="0 0 0" xyz="-4.4E-05 -0.09958 -0.013278"/>
      <mass value="1.1636"/>
      <inertia ixx="0.011088" ixy="5E-06" ixz="0" iyy="0.001072" iyz="-0.000691" izz="0.011255"/>
    </inertial>
    <visual>
      <origin rpy="0 0 0" xyz="0 0 0"/>
      <geometry>
        <mesh filename="file:///home/shinas/ros2/freddy/install/kortex_description/share/kortex_description/arms/gen3/7dof/meshes/half_arm_1_link.dae"/>
      </geometry>
      <material name="">
        <color rgba="0.75294 0.75294 0.75294 1"/>
      </material>
    </visual>
    <collision>
      <origin rpy="0 0 0" xyz="0 0 0"/>
      <geometry>
        <mesh filename="file:///home/shinas/ros2/freddy/install/kortex_description/share/kortex_description/arms/gen3/7dof/meshes/half_arm_1_link.dae"/>
      </geometry>
    </collision>
  </link>
  <joint name="kinova_left_joint_2" type="revolute">
    <origin rpy="1.5708 2.1343E-17 -1.1102E-16" xyz="0 0.005375 -0.12838"/>
    <parent link="kinova_left_shoulder_link"/>
    <child link="kinova_left_half_arm_1_link"/>
    <axis xyz="0 0 1"/>
    <limit effort="39" lower="-2.41" upper="2.41" velocity="1.3963"/>
  </joint>
  <link name="kinova_left_half_arm_2_link">
    <inertial>
      <origin rpy="0 0 0" xyz="-4.4E-05 -0.006641 -0.117892"/>
      <mass value="1.1636"/>
      <inertia ixx="0.010932" ixy="0" ixz="-7E-06" iyy="0.011127" iyz="0.000606" izz="0.001043"/>
    </inertial>
    <visual>
      <origin rpy="0 0 0" xyz="0 0 0"/>
      <geometry>
        <mesh filename="file:///home/shinas/ros2/freddy/install/kortex_description/share/kortex_description/arms/gen3/7dof/meshes/half_arm_2_link.dae"/>
      </geometry>
      <material name="">
        <color rgba="0.75294 0.75294 0.75294 1"/>
      </material>
    </visual>
    <collision>
      <origin rpy="0 0 0" xyz="0 0 0"/>
      <geometry>
        <mesh filename="file:///home/shinas/ros2/freddy/install/kortex_description/share/kortex_description/arms/gen3/7dof/meshes/half_arm_2_link.dae"/>
      </geometry>
    </collision>
  </link>
  <joint name="kinova_left_joint_3" type="continuous">
    <origin rpy="-1.5708 1.2326E-32 -2.9122E-16" xyz="0 -0.21038 -0.006375"/>
    <parent link="kinova_left_half_arm_1_link"/>
    <child link="kinova_left_half_arm_2_link"/>
    <axis xyz="0 0 1"/>
    <limit effort="39" velocity="1.3963"/>
  </joint>
  <link name="kinova_left_forearm_link">
    <inertial>
      <origin rpy="0 0 0" xyz="-1.8E-05 -0.075478 -0.015006"/>
      <mass value="0.9302"/>
      <inertia ixx="0.008147" ixy="-1E-06" ixz="0" iyy="0.000631" iyz="-0.0005" izz="0.008316"/>
    </inertial>
    <visual>
      <origin rpy="0 0 0" xyz="0 0 0"/>
      <geometry>
        <mesh filename="file:///home/shinas/ros2/freddy/install/kortex_description/share/kortex_description/arms/gen3/7dof/meshes/forearm_link.dae"/>
      </geometry>
      <material name="">
        <color rgba="0.75294 0.75294 0.75294 1"/>
      </material>
    </visual>
    <collision>
      <origin rpy="0 0 0" xyz="0 0 0"/>
      <geometry>
        <mesh filename="file:///home/shinas/ros2/freddy/install/kortex_description/share/kortex_description/arms/gen3/7dof/meshes/forearm_link.dae"/>
      </geometry>
    </collision>
  </link>
  <joint name="kinova_left_joint_4" type="revolute">
    <origin rpy="1.5708 -6.6954E-17 -1.6653E-16" xyz="0 0.006375 -0.21038"/>
    <parent link="kinova_left_half_arm_2_link"/>
    <child link="kinova_left_forearm_link"/>
    <axis xyz="0 0 1"/>
    <limit effort="39" lower="-2.66" upper="2.66" velocity="1.3963"/>
  </joint>
  <link name="kinova_left_spherical_wrist_1_link">
    <inertial>
      <origin rpy="0 0 0" xyz="1E-06 -0.009432 -0.063883"/>
      <mass value="0.6781"/>
      <inertia ixx="0.001596" ixy="0" ixz="0" iyy="0.001607" iyz="0.000256" izz="0.000399"/>
    </inertial>
    <visual>
      <origin rpy="0 0 0" xyz="0 0 0"/>
      <geometry>
        <mesh filename="file:///home/shinas/ros2/freddy/install/kortex_description/share/kortex_description/arms/gen3/7dof/meshes/spherical_wrist_1_link.dae"/>
      </geometry>
      <material name="">
        <color rgba="0.75294 0.75294 0.75294 1"/>
      </material>
    </visual>
    <collision>
      <origin rpy="0 0 0" xyz="0 0 0"/>
      <geometry>
        <mesh filename="file:///home/shinas/ros2/freddy/install/kortex_description/share/kortex_description/arms/gen3/7dof/meshes/spherical_wrist_1_link.dae"/>
      </geometry>
    </collision>
  </link>
  <joint name="kinova_left_joint_5" type="continuous">
    <origin rpy="-1.5708 2.2204E-16 -6.373E-17" xyz="0 -0.20843 -0.006375"/>
    <parent link="kinova_left_forearm_link"/>
    <child link="kinova_left_spherical_wrist_1_link"/>
    <axis xyz="0 0 1"/>
    <limit effort="9" velocity="1.2218"/>
  </joint>
  <link name="kinova_left_spherical_wrist_2_link">
    <inertial>
      <origin rpy="0 0 0" xyz="1E-06 -0.045483 -0.00965"/>
      <mass value="0.6781"/>
      <inertia ixx="0.001641" ixy="0" ixz="0" iyy="0.00041" iyz="-0.000278" izz="0.001641"/>
    </inertial>
    <visual>
      <origin rpy="0 0 0" xyz="0 0 0"/>
      <geometry>
        <mesh filename="file:///home/shinas/ros2/freddy/install/kortex_description/share/kortex_description/arms/gen3/7dof/meshes/spherical_wrist_2_link.dae"/>
      </geometry>
      <material name="">
        <color rgba="0.75294 0.75294 0.75294 1"/>
      </material>
    </visual>
    <collision>
      <origin rpy="0 0 0" xyz="0 0 0"/>
      <geometry>
        <mesh filename="file:///home/shinas/ros2/freddy/install/kortex_description/share/kortex_description/arms/gen3/7dof/meshes/spherical_wrist_2_link.dae"/>
      </geometry>
    </collision>
  </link>
  <joint name="kinova_left_joint_6" type="revolute">
    <origin rpy="1.5708 9.2076E-28 -8.2157E-15" xyz="0 0.00017505 -0.10593"/>
    <parent link="kinova_left_spherical_wrist_1_link"/>
    <child link="kinova_left_spherical_wrist_2_link"/>
    <axis xyz="0 0 1"/>
    <limit effort="9" lower="-2.23" upper="2.23" velocity="1.2218"/>
  </joint>
  <link name="kinova_left_bracelet_link">
    <inertial>
      <origin rpy="0 0 0" xyz="0.000281 0.011402 -0.029798"/>
      <mass value="0.5"/>
      <inertia ixx="0.000587" ixy="3E-06" ixz="3E-06" iyy="0.000369" iyz="-0.000118" izz="0.000609"/>
    </inertial>
    <visual>
      <origin rpy="0 0 0" xyz="0 0 0"/>
      <geometry>
        <mesh filename="file:///home/shinas/ros2/freddy/install/kortex_description/share/kortex_description/arms/gen3/7dof/meshes/bracelet_with_vision_link.dae"/>
      </geometry>
      <material name="">
        <color rgba="0.75294 0.75294 0.75294 1"/>
      </material>
    </visual>
    <collision>
      <origin rpy="0 0 0" xyz="0 0 0"/>
      <geometry>
        <mesh filename="file:///home/shinas/ros2/freddy/install/kortex_description/share/kortex_description/arms/gen3/7dof/meshes/bracelet_with_vision_link.dae"/>
      </geometry>
    </collision>
  </link>
  <joint name="kinova_left_joint_7" type="continuous">
    <origin rpy="-1.5708 -5.5511E-17 9.6396E-17" xyz="0 -0.10593 -0.00017505"/>
    <parent link="kinova_left_spherical_wrist_2_link"/>
    <child link="kinova_left_bracelet_link"/>
    <axis xyz="0 0 1"/>
    <limit effort="9" velocity="1.2218"/>
  </joint>
  <link name="kinova_left_end_effector_link"/>
  <joint name="kinova_left_end_effector" type="fixed">
    <origin rpy="3.14159265358979 1.09937075168372E-32 0" xyz="0 0 -0.0615250000000001"/>
    <parent link="kinova_left_bracelet_link"/>
    <child link="kinova_left_end_effector_link"/>
    <axis xyz="0 0 0"/>
  </joint>
  <link name="kinova_left_camera_link"/>
  <joint name="kinova_left_camera_module" type="fixed">
    <origin rpy="3.141592653589793 3.141592653589793 0" xyz="0 0.05639 -0.00305"/>
    <parent link="kinova_left_end_effector_link"/>
    <child link="kinova_left_camera_link"/>
  </joint>
  <link name="kinova_left_camera_depth_frame"/>
  <joint name="kinova_left_depth_module" type="fixed">
    <origin rpy="3.141592653589793 3.141592653589793 0" xyz="0.0275 0.066 -0.00305"/>
    <parent link="kinova_left_end_effector_link"/>
    <child link="kinova_left_camera_depth_frame"/>
  </joint>
  <link name="kinova_left_camera_color_frame"/>
  <joint name="kinova_left_color_module" type="fixed">
    <origin rpy="3.141592653589793 3.141592653589793 0" xyz="0 0.05639 -0.00305"/>
    <parent link="kinova_left_end_effector_link"/>
    <child link="kinova_left_camera_color_frame"/>
  </joint>
  <ros2_control name="RobotiqGripperHardwareInterface" type="system">
    <!-- Plugins -->
    <hardware>
      <!-- Set use_dummy to true to connect to a dummy driver for testing purposes. -->
      <param name="use_dummy">false</param>
      <plugin>robotiq_driver/RobotiqGripperHardwareInterface</plugin>
      <param name="gripper_closed_position">0.7929</param>
      <param name="COM_port">/dev/ttyUSB0</param>
      <param name="gripper_speed_multiplier">1.0</param>
      <param name="gripper_force_multiplier">0.5</param>
    </hardware>
    <!-- Joint interfaces -->
    <!-- With Ignition or Hardware, they handle mimic joints, so we only need this command interface activated -->
    <joint name="kinova_left_robotiq_85_left_knuckle_joint">
      <command_interface name="position"/>
      <state_interface name="position">
        <param name="initial_value">0.7929</param>
      </state_interface>
      <state_interface name="velocity"/>
    </joint>
    <gpio name="reactivate_gripper">
      <command_interface name="reactivate_gripper_cmd"/>
      <command_interface name="reactivate_gripper_response"/>
    </gpio>
  </ros2_control>
  <link name="kinova_left_robotiq_85_base_link">
    <visual>
      <geometry>
        <mesh filename="file:///home/shinas/ros2/freddy/install/robotiq_description/share/robotiq_description/meshes/visual/2f_85/robotiq_base.dae"/>
      </geometry>
    </visual>
    <collision>
      <geometry>
        <mesh filename="file:///home/shinas/ros2/freddy/install/robotiq_description/share/robotiq_description/meshes/collision/2f_85/robotiq_base.stl"/>
      </geometry>
    </collision>
    <inertial>
      <origin rpy="0 0 0" xyz="0.0 2.274e-05 0.03232288"/>
      <mass value="6.6320197e-01"/>
      <inertia ixx="5.1617816e-04" ixy="2.936e-8" ixz="0.0" iyy="5.8802208e-04" iyz="-3.2296e-7" izz="3.9462776e-04"/>
    </inertial>
  </link>
  <link name="kinova_left_robotiq_85_left_knuckle_link">
    <visual>
      <geometry>
        <mesh filename="file:///home/shinas/ros2/freddy/install/robotiq_description/share/robotiq_description/meshes/visual/2f_85/left_knuckle.dae"/>
      </geometry>
    </visual>
    <collision>
      <geometry>
        <mesh filename="file:///home/shinas/ros2/freddy/install/robotiq_description/share/robotiq_description/meshes/collision/2f_85/left_knuckle.stl"/>
      </geometry>
    </collision>
    <inertial>
      <origin rpy="0 0 0" xyz="0.01213197 0.0002 -0.00058647"/>
      <mass value="1.384773208e-02"/>
      <inertia ixx="3.5232e-7" ixy="0.0" ixz="1.1744e-7" iyy="2.31944e-6" iyz="0" izz="2.23136e-6"/>
    </inertial>
  </link>
  <link name="kinova_left_robotiq_85_right_knuckle_link">
    <visual>
      <geometry>
        <mesh filename="file:///home/shinas/ros2/freddy/install/robotiq_description/share/robotiq_description/meshes/visual/2f_85/right_knuckle.dae"/>
      </geometry>
    </visual>
    <collision>
      <geometry>
        <mesh filename="file:///home/shinas/ros2/freddy/install/robotiq_description/share/robotiq_description/meshes/collision/2f_85/right_knuckle.stl"/>
      </geometry>
    </collision>
    <inertial>
      <origin rpy="0 0 0" xyz="-0.01213197 0.0002 -0.00058647"/>
      <mass value="1.384773208e-02"/>
      <inertia ixx="3.5232e-7" ixy="0.0" ixz="-1.1744e-7" iyy="2.31944e-6" iyz="0.0" izz="2.23136e-6"/>
    </inertial>
  </link>
  <link name="kinova_left_robotiq_85_left_finger_link">
    <visual>
      <geometry>
        <mesh filename="file:///home/shinas/ros2/freddy/install/robotiq_description/share/robotiq_description/meshes/visual/2f_85/left_finger.dae"/>
      </geometry>
    </visual>
    <collision>
      <geometry>
        <mesh filename="file:///home/shinas/ros2/freddy/install/robotiq_description/share/robotiq_description/meshes/collision/2f_85/left_finger.stl"/>
      </geometry>
    </collision>
    <inertial>
      <origin rpy="0 0 0" xyz="0.00346899 -0.00079447 0.01867121"/>
      <mass value="4.260376752e-02"/>
      <inertia ixx="1.385792000000000e-05" ixy="0.0" ixz="-2.17264e-06" iyy="1.183208e-05" iyz="0.0" izz="5.19672e-06"/>
    </inertial>
  </link>
  <link name="kinova_left_robotiq_85_right_finger_link">
    <visual>
      <geometry>
        <mesh filename="file:///home/shinas/ros2/freddy/install/robotiq_description/share/robotiq_description/meshes/visual/2f_85/right_finger.dae"/>
      </geometry>
    </visual>
    <collision>
      <geometry>
        <mesh filename="file:///home/shinas/ros2/freddy/install/robotiq_description/share/robotiq_description/meshes/collision/2f_85/right_finger.stl"/>
      </geometry>
    </collision>
    <inertial>
      <origin rpy="0 0 0" xyz="-0.00346899 -5.53e-06 0.01867121"/>
      <mass value="4.260376752000000e-02"/>
      <inertia ixx="1.385792e-05" ixy="0.0" ixz="2.17264e-06" iyy="1.183208e-05" iyz="0.0" izz="5.19672e-06"/>
    </inertial>
  </link>
  <link name="kinova_left_robotiq_85_left_inner_knuckle_link">
    <visual>
      <geometry>
        <mesh filename="file:///home/shinas/ros2/freddy/install/robotiq_description/share/robotiq_description/meshes/visual/2f_85/left_inner_knuckle.dae"/>
      </geometry>
    </visual>
    <collision>
      <geometry>
        <mesh filename="file:///home/shinas/ros2/freddy/install/robotiq_description/share/robotiq_description/meshes/collision/2f_85/left_inner_knuckle.stl"/>
      </geometry>
    </collision>
    <inertial>
      <origin rpy="0 0 0" xyz="0.01897699 0.00015001 0.02247101"/>
      <mass value="2.969376448e-02"/>
      <inertia ixx="9.57136e-06" ixy="0.0" ixz="-3.93424e-06" iyy="8.69056e-06" iyz="0.0" izz="8.19144e-06"/>
    </inertial>
  </link>
  <link name="kinova_left_robotiq_85_right_inner_knuckle_link">
    <visual>
      <geometry>
        <mesh filename="file:///home/shinas/ros2/freddy/install/robotiq_description/share/robotiq_description/meshes/visual/2f_85/right_inner_knuckle.dae"/>
      </geometry>
    </visual>
    <collision>
      <geometry>
        <mesh filename="file:///home/shinas/ros2/freddy/install/robotiq_description/share/robotiq_description/meshes/collision/2f_85/right_inner_knuckle.stl"/>
      </geometry>
    </collision>
    <inertial>
      <origin rpy="0 0 0" xyz="-0.01926824 5.001e-05 0.02222178"/>
      <mass value="2.969376448e-02"/>
      <inertia ixx="9.42456e-06" ixy="0.0" ixz="3.9636e-06" iyy="8.69056e-06" iyz="0.0" izz="8.33824e-06"/>
    </inertial>
  </link>
  <link name="kinova_left_robotiq_85_left_finger_tip_link">
    <visual>
      <geometry>
        <mesh filename="file:///home/shinas/ros2/freddy/install/robotiq_description/share/robotiq_description/meshes/visual/2f_85/left_finger_tip.dae"/>
      </geometry>
    </visual>
    <collision>
      <geometry>
        <mesh filename="file:///home/shinas/ros2/freddy/install/robotiq_description/share/robotiq_description/meshes/collision/2f_85/left_finger_tip.stl"/>
      </geometry>
      <surface>
        <friction>
          <ode>
            <mu1>100000.0</mu1>
            <mu2>100000.0</mu2>
          </ode>
        </friction>
        <contact>
          <ode>
            <kp>1e+5</kp>
            <kd>1</kd>
            <soft_cfm>0</soft_cfm>
            <soft_erp>0.2</soft_erp>
            <minDepth>0.002</minDepth>
            <maxVel>0</maxVel>
          </ode>
        </contact>
      </surface>
    </collision>
    <inertial>
      <origin rpy="0 0 0" xyz="-0.01456706 -0.0008 0.01649701"/>
      <mass value="4.268588744e-02"/>
      <inertia ixx="1.048152e-05" ixy="0.0" ixz="3.5232e-6" iyy="1.197888e-05" iyz="0.0" izz="4.22784e-06"/>
    </inertial>
  </link>
  <link name="kinova_left_robotiq_85_right_finger_tip_link">
    <visual>
      <geometry>
        <mesh filename="file:///home/shinas/ros2/freddy/install/robotiq_description/share/robotiq_description/meshes/visual/2f_85/right_finger_tip.dae"/>
      </geometry>
    </visual>
    <collision>
      <geometry>
        <mesh filename="file:///home/shinas/ros2/freddy/install/robotiq_description/share/robotiq_description/meshes/collision/2f_85/right_finger_tip.stl"/>
      </geometry>
      <surface>
        <friction>
          <ode>
            <mu1>100000.0</mu1>
            <mu2>100000.0</mu2>
          </ode>
        </friction>
        <contact>
          <ode>
            <kp>1e+5</kp>
            <kd>1</kd>
            <soft_cfm>0</soft_cfm>
            <soft_erp>0.2</soft_erp>
            <minDepth>0.002</minDepth>
            <maxVel>0</maxVel>
          </ode>
        </contact>
      </surface>
    </collision>
    <inertial>
      <origin rpy="0 0 0" xyz="0.01456706 5e-05 0.01649701"/>
      <mass value="4.268588744e-02"/>
      <inertia ixx="1.048152e-05" ixy="0.0" ixz="-3.5232e-06" iyy="1.197888e-05" iyz="0.0" izz="4.22784e-06"/>
    </inertial>
  </link>
  <joint name="kinova_left_robotiq_85_base_joint" type="fixed">
    <parent link="kinova_left_end_effector_link"/>
    <child link="kinova_left_robotiq_85_base_link"/>
    <origin rpy="0 0 0" xyz="0 0 0"/>
  </joint>
  <joint name="kinova_left_robotiq_85_left_knuckle_joint" type="revolute">
    <parent link="kinova_left_robotiq_85_base_link"/>
    <child link="kinova_left_robotiq_85_left_knuckle_link"/>
    <axis xyz="0 -1 0"/>
    <origin rpy="0 0 0" xyz="0.03060114 0.0 0.05490452"/>
    <limit effort="50" lower="0.0" upper="0.8" velocity="0.5"/>
  </joint>
  <joint name="kinova_left_robotiq_85_right_knuckle_joint" type="revolute">
    <parent link="kinova_left_robotiq_85_base_link"/>
    <child link="kinova_left_robotiq_85_right_knuckle_link"/>
    <axis xyz="0 -1 0"/>
    <origin rpy="0 0 0" xyz="-0.03060114 0.0 0.05490452"/>
    <limit effort="50" lower="-0.8" upper="0.0" velocity="0.5"/>
    <mimic joint="kinova_left_robotiq_85_left_knuckle_joint" multiplier="-1"/>
  </joint>
  <joint name="kinova_left_robotiq_85_left_finger_joint" type="fixed">
    <parent link="kinova_left_robotiq_85_left_knuckle_link"/>
    <child link="kinova_left_robotiq_85_left_finger_link"/>
    <origin rpy="0 0 0" xyz="0.03152616 0.0 -0.00376347"/>
  </joint>
  <joint name="kinova_left_robotiq_85_right_finger_joint" type="fixed">
    <parent link="kinova_left_robotiq_85_right_knuckle_link"/>
    <child link="kinova_left_robotiq_85_right_finger_link"/>
    <origin rpy="0 0 0" xyz="-0.03152616 0.0 -0.00376347"/>
  </joint>
  <joint name="kinova_left_robotiq_85_left_inner_knuckle_joint" type="continuous">
    <parent link="kinova_left_robotiq_85_base_link"/>
    <child link="kinova_left_robotiq_85_left_inner_knuckle_link"/>
    <axis xyz="0 -1 0"/>
    <origin rpy="0 0 0" xyz="0.0127 0.0 0.06142"/>
    <mimic joint="kinova_left_robotiq_85_left_knuckle_joint"/>
  </joint>
  <joint name="kinova_left_robotiq_85_right_inner_knuckle_joint" type="continuous">
    <parent link="kinova_left_robotiq_85_base_link"/>
    <child link="kinova_left_robotiq_85_right_inner_knuckle_link"/>
    <axis xyz="0 -1 0"/>
    <origin rpy="0 0 0" xyz="-0.0127 0.0 0.06142"/>
    <mimic joint="kinova_left_robotiq_85_left_knuckle_joint" multiplier="-1"/>
  </joint>
  <joint name="kinova_left_robotiq_85_left_finger_tip_joint" type="continuous">
    <parent link="kinova_left_robotiq_85_left_finger_link"/>
    <child link="kinova_left_robotiq_85_left_finger_tip_link"/>
    <axis xyz="0 -1 0"/>
    <origin rpy="0 0 0" xyz="0.00563134 0.0 0.04718515"/>
    <mimic joint="kinova_left_robotiq_85_left_knuckle_joint" multiplier="-1"/>
  </joint>
  <joint name="kinova_left_robotiq_85_right_finger_tip_joint" type="continuous">
    <parent link="kinova_left_robotiq_85_right_finger_link"/>
    <child link="kinova_left_robotiq_85_right_finger_tip_link"/>
    <axis xyz="0 -1 0"/>
    <origin rpy="0 0 0" xyz="-0.00563134 0.0 0.04718515"/>
    <mimic joint="kinova_left_robotiq_85_left_knuckle_joint"/>
  </joint>
  <ros2_control name="kinova_right_KortexMultiInterfaceHardware" type="system">
    <hardware>
      <plugin>kortex_driver/KortexMultiInterfaceHardware</plugin>
      <param name="robot_ip">192.168.1.11</param>
      <param name="username">admin</param>
      <param name="password">admin</param>
      <param name="port">10000</param>
      <param name="port_realtime">10001</param>
      <param name="session_inactivity_timeout_ms">60000</param>
      <param name="connection_inactivity_timeout_ms">2000</param>
      <param name="tf_prefix">&quot;&quot;</param>
      <param name="use_internal_bus_gripper_comm">False</param>
      <param name="gripper_joint_name">finger_joint</param>
      <param name="gripper_max_velocity">100.0</param>
      <param name="gripper_max_force">100.0</param>
    </hardware>
    <joint name="kinova_right_joint_1">
      <command_interface name="position">
        <param name="min">{-2*pi}</param>
        <param name="max">{2*pi}</param>
      </command_interface>
      <state_interface name="position">
        <param name="initial_value">-0.517734469311598</param>
      </state_interface>
      <state_interface name="velocity"/>
      <state_interface name="effort"/>
    </joint>
    <joint name="kinova_right_joint_2">
      <command_interface name="position">
        <param name="min">-2.41</param>
        <param name="max">2.41</param>
      </command_interface>
      <state_interface name="position">
        <param name="initial_value">-0.08483200000000002</param>
      </state_interface>
      <state_interface name="velocity"/>
      <state_interface name="effort"/>
    </joint>
    <joint name="kinova_right_joint_3">
      <command_interface name="position">
        <param name="min">{-2*pi}</param>
        <param name="max">{2*pi}</param>
      </command_interface>
      <state_interface name="position">
        <param name="initial_value">1.7743715307475147</param>
      </state_interface>
      <state_interface name="velocity"/>
      <state_interface name="effort"/>
    </joint>
    <joint name="kinova_right_joint_4">
      <command_interface name="position">
        <param name="min">-2.66</param>
        <param name="max">2.66</param>
      </command_interface>
      <state_interface name="position">
        <param name="initial_value">-1.4395920000000002</param>
      </state_interface>
      <state_interface name="velocity"/>
      <state_interface name="effort"/>
    </joint>
    <joint name="kinova_right_joint_5">
      <command_interface name="position">
        <param name="min">{-2*pi}</param>
        <param name="max">{2*pi}</param>
      </command_interface>
      <state_interface name="position">
        <param name="initial_value">0.0</param>
      </state_interface>
      <state_interface name="velocity"/>
      <state_interface name="effort"/>
    </joint>
    <joint name="kinova_right_joint_6">
      <command_interface name="position">
        <param name="min">-2.23</param>
        <param name="max">2.23</param>
      </command_interface>
      <state_interface name="position">
        <param name="initial_value">-0.708248</param>
      </state_interface>
      <state_interface name="velocity"/>
      <state_interface name="effort"/>
    </joint>
    <joint name="kinova_right_joint_7">
      <command_interface name="position">
        <param name="min">{-2*pi}</param>
        <param name="max">{2*pi}</param>
      </command_interface>
      <state_interface name="position">
        <param name="initial_value">0.0</param>
      </state_interface>
      <state_interface name="velocity"/>
      <state_interface name="effort"/>
    </joint>
  </ros2_control>
  <joint name="kinova_right_base_joint" type="fixed">
    <origin rpy="0 0 0" xyz="0 0 0"/>
    <parent link="freddy_torso_shoulder_right_arm_attach_link"/>
    <child link="kinova_right_base_link"/>
  </joint>
  <link name="kinova_right_base_link">
    <inertial>
      <origin rpy="0 0 0" xyz="-0.000648 -0.000166 0.084487"/>
      <mass value="1.697"/>
      <inertia ixx="0.004622" ixy="9E-06" ixz="6E-05" iyy="0.004495" iyz="9E-06" izz="0.002079"/>
    </inertial>
    <visual>
      <origin rpy="0 0 0" xyz="0 0 0"/>
      <geometry>
        <mesh filename="file:///home/shinas/ros2/freddy/install/kortex_description/share/kortex_description/arms/gen3/7dof/meshes/base_link.dae"/>
      </geometry>
      <material name="">
        <color rgba="0.75294 0.75294 0.75294 1"/>
      </material>
    </visual>
    <collision>
      <origin rpy="0 0 0" xyz="0 0 0"/>
      <geometry>
        <mesh filename="file:///home/shinas/ros2/freddy/install/kortex_description/share/kortex_description/arms/gen3/7dof/meshes/base_link.dae"/>
      </geometry>
    </collision>
  </link>
  <link name="kinova_right_shoulder_link">
    <inertial>
      <origin rpy="0 0 0" xyz="-2.3E-05 -0.010364 -0.07336"/>
      <mass value="1.3773"/>
      <inertia ixx="0.00457" ixy="1E-06" ixz="2E-06" iyy="0.004831" iyz="0.000448" izz="0.001409"/>
    </inertial>
    <visual>
      <origin rpy="0 0 0" xyz="0 0 0"/>
      <geometry>
        <mesh filename="file:///home/shinas/ros2/freddy/install/kortex_description/share/kortex_description/arms/gen3/7dof/meshes/shoulder_link.dae"/>
      </geometry>
      <material name="">
        <color rgba="0.75294 0.75294 0.75294 1"/>
      </material>
    </visual>
    <collision>
      <origin rpy="0 0 0" xyz="0 0 0"/>
      <geometry>
        <mesh filename="file:///home/shinas/ros2/freddy/install/kortex_description/share/kortex_description/arms/gen3/7dof/meshes/shoulder_link.dae"/>
      </geometry>
    </collision>
  </link>
  <joint name="kinova_right_joint_1" type="continuous">
    <origin rpy="3.1416 2.7629E-18 -4.9305E-36" xyz="0 0 0.15643"/>
    <parent link="kinova_right_base_link"/>
    <child link="kinova_right_shoulder_link"/>
    <axis xyz="0 0 1"/>
    <limit effort="39" velocity="1.3963"/>
  </joint>
  <link name="kinova_right_half_arm_1_link">
    <inertial>
      <origin rpy="0 0 0" xyz="-4.4E-05 -0.09958 -0.013278"/>
      <mass value="1.1636"/>
      <inertia ixx="0.011088" ixy="5E-06" ixz="0" iyy="0.001072" iyz="-0.000691" izz="0.011255"/>
    </inertial>
    <visual>
      <origin rpy="0 0 0" xyz="0 0 0"/>
      <geometry>
        <mesh filename="file:///home/shinas/ros2/freddy/install/kortex_description/share/kortex_description/arms/gen3/7dof/meshes/half_arm_1_link.dae"/>
      </geometry>
      <material name="">
        <color rgba="0.75294 0.75294 0.75294 1"/>
      </material>
    </visual>
    <collision>
      <origin rpy="0 0 0" xyz="0 0 0"/>
      <geometry>
        <mesh filename="file:///home/shinas/ros2/freddy/install/kortex_description/share/kortex_description/arms/gen3/7dof/meshes/half_arm_1_link.dae"/>
      </geometry>
    </collision>
  </link>
  <joint name="kinova_right_joint_2" type="revolute">
    <origin rpy="1.5708 2.1343E-17 -1.1102E-16" xyz="0 0.005375 -0.12838"/>
    <parent link="kinova_right_shoulder_link"/>
    <child link="kinova_right_half_arm_1_link"/>
    <axis xyz="0 0 1"/>
    <limit effort="39" lower="-2.41" upper="2.41" velocity="1.3963"/>
  </joint>
  <link name="kinova_right_half_arm_2_link">
    <inertial>
      <origin rpy="0 0 0" xyz="-4.4E-05 -0.006641 -0.117892"/>
      <mass value="1.1636"/>
      <inertia ixx="0.010932" ixy="0" ixz="-7E-06" iyy="0.011127" iyz="0.000606" izz="0.001043"/>
    </inertial>
    <visual>
      <origin rpy="0 0 0" xyz="0 0 0"/>
      <geometry>
        <mesh filename="file:///home/shinas/ros2/freddy/install/kortex_description/share/kortex_description/arms/gen3/7dof/meshes/half_arm_2_link.dae"/>
      </geometry>
      <material name="">
        <color rgba="0.75294 0.75294 0.75294 1"/>
      </material>
    </visual>
    <collision>
      <origin rpy="0 0 0" xyz="0 0 0"/>
      <geometry>
        <mesh filename="file:///home/shinas/ros2/freddy/install/kortex_description/share/kortex_description/arms/gen3/7dof/meshes/half_arm_2_link.dae"/>
      </geometry>
    </collision>
  </link>
  <joint name="kinova_right_joint_3" type="continuous">
    <origin rpy="-1.5708 1.2326E-32 -2.9122E-16" xyz="0 -0.21038 -0.006375"/>
    <parent link="kinova_right_half_arm_1_link"/>
    <child link="kinova_right_half_arm_2_link"/>
    <axis xyz="0 0 1"/>
    <limit effort="39" velocity="1.3963"/>
  </joint>
  <link name="kinova_right_forearm_link">
    <inertial>
      <origin rpy="0 0 0" xyz="-1.8E-05 -0.075478 -0.015006"/>
      <mass value="0.9302"/>
      <inertia ixx="0.008147" ixy="-1E-06" ixz="0" iyy="0.000631" iyz="-0.0005" izz="0.008316"/>
    </inertial>
    <visual>
      <origin rpy="0 0 0" xyz="0 0 0"/>
      <geometry>
        <mesh filename="file:///home/shinas/ros2/freddy/install/kortex_description/share/kortex_description/arms/gen3/7dof/meshes/forearm_link.dae"/>
      </geometry>
      <material name="">
        <color rgba="0.75294 0.75294 0.75294 1"/>
      </material>
    </visual>
    <collision>
      <origin rpy="0 0 0" xyz="0 0 0"/>
      <geometry>
        <mesh filename="file:///home/shinas/ros2/freddy/install/kortex_description/share/kortex_description/arms/gen3/7dof/meshes/forearm_link.dae"/>
      </geometry>
    </collision>
  </link>
  <joint name="kinova_right_joint_4" type="revolute">
    <origin rpy="1.5708 -6.6954E-17 -1.6653E-16" xyz="0 0.006375 -0.21038"/>
    <parent link="kinova_right_half_arm_2_link"/>
    <child link="kinova_right_forearm_link"/>
    <axis xyz="0 0 1"/>
    <limit effort="39" lower="-2.66" upper="2.66" velocity="1.3963"/>
  </joint>
  <link name="kinova_right_spherical_wrist_1_link">
    <inertial>
      <origin rpy="0 0 0" xyz="1E-06 -0.009432 -0.063883"/>
      <mass value="0.6781"/>
      <inertia ixx="0.001596" ixy="0" ixz="0" iyy="0.001607" iyz="0.000256" izz="0.000399"/>
    </inertial>
    <visual>
      <origin rpy="0 0 0" xyz="0 0 0"/>
      <geometry>
        <mesh filename="file:///home/shinas/ros2/freddy/install/kortex_description/share/kortex_description/arms/gen3/7dof/meshes/spherical_wrist_1_link.dae"/>
      </geometry>
      <material name="">
        <color rgba="0.75294 0.75294 0.75294 1"/>
      </material>
    </visual>
    <collision>
      <origin rpy="0 0 0" xyz="0 0 0"/>
      <geometry>
        <mesh filename="file:///home/shinas/ros2/freddy/install/kortex_description/share/kortex_description/arms/gen3/7dof/meshes/spherical_wrist_1_link.dae"/>
      </geometry>
    </collision>
  </link>
  <joint name="kinova_right_joint_5" type="continuous">
    <origin rpy="-1.5708 2.2204E-16 -6.373E-17" xyz="0 -0.20843 -0.006375"/>
    <parent link="kinova_right_forearm_link"/>
    <child link="kinova_right_spherical_wrist_1_link"/>
    <axis xyz="0 0 1"/>
    <limit effort="9" velocity="1.2218"/>
  </joint>
  <link name="kinova_right_spherical_wrist_2_link">
    <inertial>
      <origin rpy="0 0 0" xyz="1E-06 -0.045483 -0.00965"/>
      <mass value="0.6781"/>
      <inertia ixx="0.001641" ixy="0" ixz="0" iyy="0.00041" iyz="-0.000278" izz="0.001641"/>
    </inertial>
    <visual>
      <origin rpy="0 0 0" xyz="0 0 0"/>
      <geometry>
        <mesh filename="file:///home/shinas/ros2/freddy/install/kortex_description/share/kortex_description/arms/gen3/7dof/meshes/spherical_wrist_2_link.dae"/>
      </geometry>
      <material name="">
        <color rgba="0.75294 0.75294 0.75294 1"/>
      </material>
    </visual>
    <collision>
      <origin rpy="0 0 0" xyz="0 0 0"/>
      <geometry>
        <mesh filename="file:///home/shinas/ros2/freddy/install/kortex_description/share/kortex_description/arms/gen3/7dof/meshes/spherical_wrist_2_link.dae"/>
      </geometry>
    </collision>
  </link>
  <joint name="kinova_right_joint_6" type="revolute">
    <origin rpy="1.5708 9.2076E-28 -8.2157E-15" xyz="0 0.00017505 -0.10593"/>
    <parent link="kinova_right_spherical_wrist_1_link"/>
    <child link="kinova_right_spherical_wrist_2_link"/>
    <axis xyz="0 0 1"/>
    <limit effort="9" lower="-2.23" upper="2.23" velocity="1.2218"/>
  </joint>
  <link name="kinova_right_bracelet_link">
    <inertial>
      <origin rpy="0 0 0" xyz="0.000281 0.011402 -0.029798"/>
      <mass value="0.5"/>
      <inertia ixx="0.000587" ixy="3E-06" ixz="3E-06" iyy="0.000369" iyz="-0.000118" izz="0.000609"/>
    </inertial>
    <visual>
      <origin rpy="0 0 0" xyz="0 0 0"/>
      <geometry>
        <mesh filename="file:///home/shinas/ros2/freddy/install/kortex_description/share/kortex_description/arms/gen3/7dof/meshes/bracelet_with_vision_link.dae"/>
      </geometry>
      <material name="">
        <color rgba="0.75294 0.75294 0.75294 1"/>
      </material>
    </visual>
    <collision>
      <origin rpy="0 0 0" xyz="0 0 0"/>
      <geometry>
        <mesh filename="file:///home/shinas/ros2/freddy/install/kortex_description/share/kortex_description/arms/gen3/7dof/meshes/bracelet_with_vision_link.dae"/>
      </geometry>
    </collision>
  </link>
  <joint name="kinova_right_joint_7" type="continuous">
    <origin rpy="-1.5708 -5.5511E-17 9.6396E-17" xyz="0 -0.10593 -0.00017505"/>
    <parent link="kinova_right_spherical_wrist_2_link"/>
    <child link="kinova_right_bracelet_link"/>
    <axis xyz="0 0 1"/>
    <limit effort="9" velocity="1.2218"/>
  </joint>
  <link name="kinova_right_end_effector_link"/>
  <joint name="kinova_right_end_effector" type="fixed">
    <origin rpy="3.14159265358979 1.09937075168372E-32 0" xyz="0 0 -0.0615250000000001"/>
    <parent link="kinova_right_bracelet_link"/>
    <child link="kinova_right_end_effector_link"/>
    <axis xyz="0 0 0"/>
  </joint>
  <link name="kinova_right_camera_link"/>
  <joint name="kinova_right_camera_module" type="fixed">
    <origin rpy="3.141592653589793 3.141592653589793 0" xyz="0 0.05639 -0.00305"/>
    <parent link="kinova_right_end_effector_link"/>
    <child link="kinova_right_camera_link"/>
  </joint>
  <link name="kinova_right_camera_depth_frame"/>
  <joint name="kinova_right_depth_module" type="fixed">
    <origin rpy="3.141592653589793 3.141592653589793 0" xyz="0.0275 0.066 -0.00305"/>
    <parent link="kinova_right_end_effector_link"/>
    <child link="kinova_right_camera_depth_frame"/>
  </joint>
  <link name="kinova_right_camera_color_frame"/>
  <joint name="kinova_right_color_module" type="fixed">
    <origin rpy="3.141592653589793 3.141592653589793 0" xyz="0 0.05639 -0.00305"/>
    <parent link="kinova_right_end_effector_link"/>
    <child link="kinova_right_camera_color_frame"/>
  </joint>
  <ros2_control name="RobotiqGripperHardwareInterface" type="system">
    <!-- Plugins -->
    <hardware>
      <!-- Set use_dummy to true to connect to a dummy driver for testing purposes. -->
      <param name="use_dummy">false</param>
      <plugin>robotiq_driver/RobotiqGripperHardwareInterface</plugin>
      <param name="gripper_closed_position">0.7929</param>
      <param name="COM_port">/dev/ttyUSB0</param>
      <param name="gripper_speed_multiplier">1.0</param>
      <param name="gripper_force_multiplier">0.5</param>
    </hardware>
    <!-- Joint interfaces -->
    <!-- With Ignition or Hardware, they handle mimic joints, so we only need this command interface activated -->
    <joint name="kinova_right_robotiq_85_left_knuckle_joint">
      <command_interface name="position"/>
      <state_interface name="position">
        <param name="initial_value">0.7929</param>
      </state_interface>
      <state_interface name="velocity"/>
    </joint>
    <gpio name="reactivate_gripper">
      <command_interface name="reactivate_gripper_cmd"/>
      <command_interface name="reactivate_gripper_response"/>
    </gpio>
  </ros2_control>
  <link name="kinova_right_robotiq_85_base_link">
    <visual>
      <geometry>
        <mesh filename="file:///home/shinas/ros2/freddy/install/robotiq_description/share/robotiq_description/meshes/visual/2f_85/robotiq_base.dae"/>
      </geometry>
    </visual>
    <collision>
      <geometry>
        <mesh filename="file:///home/shinas/ros2/freddy/install/robotiq_description/share/robotiq_description/meshes/collision/2f_85/robotiq_base.stl"/>
      </geometry>
    </collision>
    <inertial>
      <origin rpy="0 0 0" xyz="0.0 2.274e-05 0.03232288"/>
      <mass value="6.6320197e-01"/>
      <inertia ixx="5.1617816e-04" ixy="2.936e-8" ixz="0.0" iyy="5.8802208e-04" iyz="-3.2296e-7" izz="3.9462776e-04"/>
    </inertial>
  </link>
  <link name="kinova_right_robotiq_85_left_knuckle_link">
    <visual>
      <geometry>
        <mesh filename="file:///home/shinas/ros2/freddy/install/robotiq_description/share/robotiq_description/meshes/visual/2f_85/left_knuckle.dae"/>
      </geometry>
    </visual>
    <collision>
      <geometry>
        <mesh filename="file:///home/shinas/ros2/freddy/install/robotiq_description/share/robotiq_description/meshes/collision/2f_85/left_knuckle.stl"/>
      </geometry>
    </collision>
    <inertial>
      <origin rpy="0 0 0" xyz="0.01213197 0.0002 -0.00058647"/>
      <mass value="1.384773208e-02"/>
      <inertia ixx="3.5232e-7" ixy="0.0" ixz="1.1744e-7" iyy="2.31944e-6" iyz="0" izz="2.23136e-6"/>
    </inertial>
  </link>
  <link name="kinova_right_robotiq_85_right_knuckle_link">
    <visual>
      <geometry>
        <mesh filename="file:///home/shinas/ros2/freddy/install/robotiq_description/share/robotiq_description/meshes/visual/2f_85/right_knuckle.dae"/>
      </geometry>
    </visual>
    <collision>
      <geometry>
        <mesh filename="file:///home/shinas/ros2/freddy/install/robotiq_description/share/robotiq_description/meshes/collision/2f_85/right_knuckle.stl"/>
      </geometry>
    </collision>
    <inertial>
      <origin rpy="0 0 0" xyz="-0.01213197 0.0002 -0.00058647"/>
      <mass value="1.384773208e-02"/>
      <inertia ixx="3.5232e-7" ixy="0.0" ixz="-1.1744e-7" iyy="2.31944e-6" iyz="0.0" izz="2.23136e-6"/>
    </inertial>
  </link>
  <link name="kinova_right_robotiq_85_left_finger_link">
    <visual>
      <geometry>
        <mesh filename="file:///home/shinas/ros2/freddy/install/robotiq_description/share/robotiq_description/meshes/visual/2f_85/left_finger.dae"/>
      </geometry>
    </visual>
    <collision>
      <geometry>
        <mesh filename="file:///home/shinas/ros2/freddy/install/robotiq_description/share/robotiq_description/meshes/collision/2f_85/left_finger.stl"/>
      </geometry>
    </collision>
    <inertial>
      <origin rpy="0 0 0" xyz="0.00346899 -0.00079447 0.01867121"/>
      <mass value="4.260376752e-02"/>
      <inertia ixx="1.385792000000000e-05" ixy="0.0" ixz="-2.17264e-06" iyy="1.183208e-05" iyz="0.0" izz="5.19672e-06"/>
    </inertial>
  </link>
  <link name="kinova_right_robotiq_85_right_finger_link">
    <visual>
      <geometry>
        <mesh filename="file:///home/shinas/ros2/freddy/install/robotiq_description/share/robotiq_description/meshes/visual/2f_85/right_finger.dae"/>
      </geometry>
    </visual>
    <collision>
      <geometry>
        <mesh filename="file:///home/shinas/ros2/freddy/install/robotiq_description/share/robotiq_description/meshes/collision/2f_85/right_finger.stl"/>
      </geometry>
    </collision>
    <inertial>
      <origin rpy="0 0 0" xyz="-0.00346899 -5.53e-06 0.01867121"/>
      <mass value="4.260376752000000e-02"/>
      <inertia ixx="1.385792e-05" ixy="0.0" ixz="2.17264e-06" iyy="1.183208e-05" iyz="0.0" izz="5.19672e-06"/>
    </inertial>
  </link>
  <link name="kinova_right_robotiq_85_left_inner_knuckle_link">
    <visual>
      <geometry>
        <mesh filename="file:///home/shinas/ros2/freddy/install/robotiq_description/share/robotiq_description/meshes/visual/2f_85/left_inner_knuckle.dae"/>
      </geometry>
    </visual>
    <collision>
      <geometry>
        <mesh filename="file:///home/shinas/ros2/freddy/install/robotiq_description/share/robotiq_description/meshes/collision/2f_85/left_inner_knuckle.stl"/>
      </geometry>
    </collision>
    <inertial>
      <origin rpy="0 0 0" xyz="0.01897699 0.00015001 0.02247101"/>
      <mass value="2.969376448e-02"/>
      <inertia ixx="9.57136e-06" ixy="0.0" ixz="-3.93424e-06" iyy="8.69056e-06" iyz="0.0" izz="8.19144e-06"/>
    </inertial>
  </link>
  <link name="kinova_right_robotiq_85_right_inner_knuckle_link">
    <visual>
      <geometry>
        <mesh filename="file:///home/shinas/ros2/freddy/install/robotiq_description/share/robotiq_description/meshes/visual/2f_85/right_inner_knuckle.dae"/>
      </geometry>
    </visual>
    <collision>
      <geometry>
        <mesh filename="file:///home/shinas/ros2/freddy/install/robotiq_description/share/robotiq_description/meshes/collision/2f_85/right_inner_knuckle.stl"/>
      </geometry>
    </collision>
    <inertial>
      <origin rpy="0 0 0" xyz="-0.01926824 5.001e-05 0.02222178"/>
      <mass value="2.969376448e-02"/>
      <inertia ixx="9.42456e-06" ixy="0.0" ixz="3.9636e-06" iyy="8.69056e-06" iyz="0.0" izz="8.33824e-06"/>
    </inertial>
  </link>
  <link name="kinova_right_robotiq_85_left_finger_tip_link">
    <visual>
      <geometry>
        <mesh filename="file:///home/shinas/ros2/freddy/install/robotiq_description/share/robotiq_description/meshes/visual/2f_85/left_finger_tip.dae"/>
      </geometry>
    </visual>
    <collision>
      <geometry>
        <mesh filename="file:///home/shinas/ros2/freddy/install/robotiq_description/share/robotiq_description/meshes/collision/2f_85/left_finger_tip.stl"/>
      </geometry>
      <surface>
        <friction>
          <ode>
            <mu1>100000.0</mu1>
            <mu2>100000.0</mu2>
          </ode>
        </friction>
        <contact>
          <ode>
            <kp>1e+5</kp>
            <kd>1</kd>
            <soft_cfm>0</soft_cfm>
            <soft_erp>0.2</soft_erp>
            <minDepth>0.002</minDepth>
            <maxVel>0</maxVel>
          </ode>
        </contact>
      </surface>
    </collision>
    <inertial>
      <origin rpy="0 0 0" xyz="-0.01456706 -0.0008 0.01649701"/>
      <mass value="4.268588744e-02"/>
      <inertia ixx="1.048152e-05" ixy="0.0" ixz="3.5232e-6" iyy="1.197888e-05" iyz="0.0" izz="4.22784e-06"/>
    </inertial>
  </link>
  <link name="kinova_right_robotiq_85_right_finger_tip_link">
    <visual>
      <geometry>
        <mesh filename="file:///home/shinas/ros2/freddy/install/robotiq_description/share/robotiq_description/meshes/visual/2f_85/right_finger_tip.dae"/>
      </geometry>
    </visual>
    <collision>
      <geometry>
        <mesh filename="file:///home/shinas/ros2/freddy/install/robotiq_description/share/robotiq_description/meshes/collision/2f_85/right_finger_tip.stl"/>
      </geometry>
      <surface>
        <friction>
          <ode>
            <mu1>100000.0</mu1>
            <mu2>100000.0</mu2>
          </ode>
        </friction>
        <contact>
          <ode>
            <kp>1e+5</kp>
            <kd>1</kd>
            <soft_cfm>0</soft_cfm>
            <soft_erp>0.2</soft_erp>
            <minDepth>0.002</minDepth>
            <maxVel>0</maxVel>
          </ode>
        </contact>
      </surface>
    </collision>
    <inertial>
      <origin rpy="0 0 0" xyz="0.01456706 5e-05 0.01649701"/>
      <mass value="4.268588744e-02"/>
      <inertia ixx="1.048152e-05" ixy="0.0" ixz="-3.5232e-06" iyy="1.197888e-05" iyz="0.0" izz="4.22784e-06"/>
    </inertial>
  </link>
  <joint name="kinova_right_robotiq_85_base_joint" type="fixed">
    <parent link="kinova_right_end_effector_link"/>
    <child link="kinova_right_robotiq_85_base_link"/>
    <origin rpy="0 0 0" xyz="0 0 0"/>
  </joint>
  <joint name="kinova_right_robotiq_85_left_knuckle_joint" type="revolute">
    <parent link="kinova_right_robotiq_85_base_link"/>
    <child link="kinova_right_robotiq_85_left_knuckle_link"/>
    <axis xyz="0 -1 0"/>
    <origin rpy="0 0 0" xyz="0.03060114 0.0 0.05490452"/>
    <limit effort="50" lower="0.0" upper="0.8" velocity="0.5"/>
  </joint>
  <joint name="kinova_right_robotiq_85_right_knuckle_joint" type="revolute">
    <parent link="kinova_right_robotiq_85_base_link"/>
    <child link="kinova_right_robotiq_85_right_knuckle_link"/>
    <axis xyz="0 -1 0"/>
    <origin rpy="0 0 0" xyz="-0.03060114 0.0 0.05490452"/>
    <limit effort="50" lower="-0.8" upper="0.0" velocity="0.5"/>
    <mimic joint="kinova_right_robotiq_85_left_knuckle_joint" multiplier="-1"/>
  </joint>
  <joint name="kinova_right_robotiq_85_left_finger_joint" type="fixed">
    <parent link="kinova_right_robotiq_85_left_knuckle_link"/>
    <child link="kinova_right_robotiq_85_left_finger_link"/>
    <origin rpy="0 0 0" xyz="0.03152616 0.0 -0.00376347"/>
  </joint>
  <joint name="kinova_right_robotiq_85_right_finger_joint" type="fixed">
    <parent link="kinova_right_robotiq_85_right_knuckle_link"/>
    <child link="kinova_right_robotiq_85_right_finger_link"/>
    <origin rpy="0 0 0" xyz="-0.03152616 0.0 -0.00376347"/>
  </joint>
  <joint name="kinova_right_robotiq_85_left_inner_knuckle_joint" type="continuous">
    <parent link="kinova_right_robotiq_85_base_link"/>
    <child link="kinova_right_robotiq_85_left_inner_knuckle_link"/>
    <axis xyz="0 -1 0"/>
    <origin rpy="0 0 0" xyz="0.0127 0.0 0.06142"/>
    <mimic joint="kinova_right_robotiq_85_left_knuckle_joint"/>
  </joint>
  <joint name="kinova_right_robotiq_85_right_inner_knuckle_joint" type="continuous">
    <parent link="kinova_right_robotiq_85_base_link"/>
    <child link="kinova_right_robotiq_85_right_inner_knuckle_link"/>
    <axis xyz="0 -1 0"/>
    <origin rpy="0 0 0" xyz="-0.0127 0.0 0.06142"/>
    <mimic joint="kinova_right_robotiq_85_left_knuckle_joint" multiplier="-1"/>
  </joint>
  <joint name="kinova_right_robotiq_85_left_finger_tip_joint" type="continuous">
    <parent link="kinova_right_robotiq_85_left_finger_link"/>
    <child link="kinova_right_robotiq_85_left_finger_tip_link"/>
    <axis xyz="0 -1 0"/>
    <origin rpy="0 0 0" xyz="0.00563134 0.0 0.04718515"/>
    <mimic joint="kinova_right_robotiq_85_left_knuckle_joint" multiplier="-1"/>
  </joint>
  <joint name="kinova_right_robotiq_85_right_finger_tip_joint" type="continuous">
    <parent link="kinova_right_robotiq_85_right_finger_link"/>
    <child link="kinova_right_robotiq_85_right_finger_tip_link"/>
    <axis xyz="0 -1 0"/>
    <origin rpy="0 0 0" xyz="-0.00563134 0.0 0.04718515"/>
    <mimic joint="kinova_right_robotiq_85_left_knuckle_joint"/>
  </joint>
  <!-- grasp links -->
  <link name="kinova_left_grasp_link"/>
  <link name="kinova_right_grasp_link"/>
  <!-- grasp link joints -->
  <joint name="kinova_left_grasp_link_joint" type="fixed">
    <origin rpy="0 0 0" xyz="0 0 0.15"/>
    <parent link="kinova_left_robotiq_85_base_link"/>
    <child link="kinova_left_grasp_link"/>
  </joint>
  <joint name="kinova_right_grasp_link_joint" type="fixed">
    <origin rpy="0 0 0" xyz="0 0 0.15"/>
    <parent link="kinova_right_robotiq_85_base_link"/>
    <child link="kinova_right_grasp_link"/>
  </joint>
</robot>
